Workbook

Sheet Portada
B2: EXPERIMENTO PROYECTO INCERTIDUMBRES
B4: Realizado por:
B6: Sebastián Chaves Rojas
B7: John Fred Granados Gomez
B8: Carlos Manuel Navarro Mora
B9: Andrés Rodriguez Gamboa
B10: Alejandro Torres Venegas

Sheet Datos
B2: Datos Constantes | T2: Datos por iteración
B4: Masa de esfera: | C4: =AVERAGE(C11:C16) -> 0.00688103 | D4: kg | F4: Diámetro esfera: | G4: =AVERAGE(G11:G1048576) -> 0.011866667 | H4: m | J4: Temperatura ambiente: | K4: =AVERAGE(K11:K1048576) -> 28.6 | L4: °C | N4: Capacidad calorífica: | O4: =0.45*1000 -> 450 | P4: J/(kg K) | T4: Tiempo de enfriamiento: | U4: =AVERAGE(U11:U1048576) -> 270 | V4: s | X4: Temperatura inicial: | Y4: =AVERAGE(Y11:Y1048576) -> 84.9 | Z4: °C | AB4: Temperatura final: | AC4: =AVERAGE(AC11:AC1048576) -> 42.49 | AD4: °C
O5: Según Brown
B6: Resolución balanza: | C6: =0.00001*10^-3 -> 1e-08 | D6: kg | F6: Resolución vernier: | G6: =0.01*10^-3 -> 1e-05 | H6: m | J6: Resolución multímetro: | K6: 0.1 | L6: °C | T6: Resolución temporal: | U6: =1/60 -> 0.016666667 | V6: s | X6: Resolución multímetro: | Y6: 0.1 | Z6: °C | AB6: Resolución multímetro: | AC6: 0.1 | AD6: °C
B7: Certificado balanza: | C7: =0.002*10^-3 -> 2e-06 | D7: kg | F7: Certificado vernier: | G7: =0.02*10^-3 -> 2e-05 | H7: m | J7: Certificado multímetro: | K7: 0.6 | L7: °C | T7: Desviación estándar: | U7: =_xlfn.STDEV.S(U11:U1048576) -> 0 | V7: s | X7: Certificado multímetro: | Y7: 0.6 | Z7: °C | AB7: Certificado multímetro: | AC7: 0.6 | AD7: °C
B8: Desviación estándar: | C8: =_xlfn.STDEV.S(C11:C1048576) -> 5.4405882e-08 | D8: kg | F8: Desviación estándar | G8: =_xlfn.STDEV.S(G11:G1048576) -> 5.1639778e-06 | H8: m | J8: Desviación estándar: | K8: =_xlfn.STDEV.S(K11:K1048576) -> 0.32317866 | L8: °C | X8: Desviación estándar: | Y8: =_xlfn.STDEV.S(Y11:Y20) -> 5.2637123 | Z8: °C | AB8: Desviación estándar: | AC8: =_xlfn.STDEV.S(AC11:AC20) -> 1.555242 | AD8: °C
B10: Datos: | C10: m | F10: Datos: | G10: D | J10: Datos | K10: T∞ | T10: Datos: | U10: τ | X10: Datos | Y10: T0 | AB10: Datos | AC10: T(τ) | AI10: k
C11: 0.006881 | D11: =IF(C11,"kg","") -> kg | G11: 0.01187 | H11: =IF(G11,"m","") -> m | K11: 28.1 | L11: =IF(K11,"°C","") -> °C | U11: =4*60+30 -> 270 | V11: =IF(U11,"s","") -> s | Y11: 83.7 | Z11: =IF(Y11,"°C","") -> °C | AC11: 42.5 | AD11: =IF(AC11,"°C","") -> °C | AI11: =-1/U11*LN((AC11-$K$4)/(Y11-$K$4)) -> 0.0051009662 | AJ11: s-1
C12: 0.00688098 | D12: =IF(C12,"kg","") -> kg | G12: 0.01187 | H12: =IF(G12,"m","") -> m | K12: 28.5 | L12: =IF(K12,"°C","") -> °C | U12: =4*60+30 -> 270 | V12: =IF(U12,"s","") -> s | Y12: 79.8 | Z12: =IF(Y12,"°C","") -> °C | AC12: 41.8 | AD12: =IF(AC12,"°C","") -> °C | AI12: =-1/U12*LN((AC12-$K$4)/(Y12-$K$4)) -> 0.0050204545 | AJ12: s-1
C13: 0.00688098 | D13: =IF(C13,"kg","") -> kg | G13: 0.01186 | H13: =IF(G13,"m","") -> m | K13: 28.7 | L13: =IF(K13,"°C","") -> °C | U13: =4*60+30 -> 270 | V13: =IF(U13,"s","") -> s | Y13: 79.9 | Z13: =IF(Y13,"°C","") -> °C | AC13: 42.6 | AD13: =IF(AC13,"°C","") -> °C | AI13: =-1/U13*LN((AC13-$K$4)/(Y13-$K$4)) -> 0.0048097534 | AJ13: s-1
C14: 0.00688111 | D14: =IF(C14,"kg","") -> kg | G14: 0.01187 | H14: =IF(G14,"m","") -> m | K14: 28.9 | L14: =IF(K14,"°C","") -> °C | U14: =4*60+30 -> 270 | V14: =IF(U14,"s","") -> s | Y14: 76.6 | Z14: =IF(Y14,"°C","") -> °C | AC14: 40.2 | AD14: =IF(AC14,"°C","") -> °C | AI14: =-1/U14*LN((AC14-$K$4)/(Y14-$K$4)) -> 0.0052599849 | AJ14: s-1
C15: 0.00688108 | D15: =IF(C15,"kg","") -> kg | G15: 0.01187 | H15: =IF(G15,"m","") -> m | K15: 28.6 | L15: =IF(K15,"°C","") -> °C | U15: =4*60+30 -> 270 | V15: =IF(U15,"s","") -> s | Y15: 81.5 | Z15: =IF(Y15,"°C","") -> °C | AC15: 41.2 | AD15: =IF(AC15,"°C","") -> °C | AI15: =-1/U15*LN((AC15-$K$4)/(Y15-$K$4)) -> 0.0053137279 | AJ15: s-1
C16: 0.00688103 | D16: =IF(C16,"kg","") -> kg | G16: 0.01186 | H16: =IF(G16,"m","") -> m | K16: 28.8 | L16: =IF(K15,"°C","") -> °C | U16: =4*60+30 -> 270 | V16: =IF(U16,"s","") -> s | Y16: 89.3 | Z16: =IF(Y16,"°C","") -> °C | AC16: 43.5 | AD16: =IF(AC16,"°C","") -> °C | AI16: =-1/U16*LN((AC16-$K$4)/(Y16-$K$4)) -> 0.0052021574 | AJ16: s-1
D17: =IF(C17,"kg","") | H17: =IF(G17,"m","") | K17: 29.2 | L17: =IF(K15,"°C","") -> °C | U17: =4*60+30 -> 270 | V17: =IF(U17,"s","") -> s | Y17: 91.2 | Z17: =IF(Y17,"°C","") -> °C | AC17: 41.7 | AD17: =IF(AC17,"°C","") -> °C | AI17: =-1/U17*LN((AC17-$K$4)/(Y17-$K$4)) -> 0.0057931594 | AJ17: s-1
D18: =IF(C18,"kg","") | H18: =IF(G18,"m","") | K18: 28.6 | L18: =IF(K15,"°C","") -> °C | U18: =4*60+30 -> 270 | V18: =IF(U18,"s","") -> s | Y18: 87.3 | Z18: =IF(Y18,"°C","") -> °C | AC18: 43.1 | AD18: =IF(AC18,"°C","") -> °C | AI18: =-1/U18*LN((AC18-$K$4)/(Y18-$K$4)) -> 0.0051788558 | AJ18: s-1
D19: =IF(C19,"kg","") | H19: =IF(G19,"m","") | K19: 28.3 | L19: =IF(K15,"°C","") -> °C | U19: =4*60+30 -> 270 | V19: =IF(U19,"s","") -> s | Y19: 88.7 | Z19: =IF(Y19,"°C","") -> °C | AC19: 42.3 | AD19: =IF(AC19,"°C","") -> °C | AI19: =-1/U19*LN((AC19-$K$4)/(Y19-$K$4)) -> 0.0054763482 | AJ19: s-1
D20: =IF(C20,"kg","") | H20: =IF(G20,"m","") | K20: 28.3 | L20: =IF(K20,"°C","") -> °C | U20: 270 | V20: s | Y20: 91 | Z20: =IF(Y20,"°C","") -> °C | AC20: 46 | AD20: =IF(AC20,"°C","") -> °C | AI20: =-1/U20*LN((AC20-$K$4)/(Y20-$K$4)) -> 0.0047299817 | AJ20: s-1
D21: =IF(C21,"kg","") | H21: =IF(G21,"m","") | L21: =IF(K21,"°C","") | V21: =IF(U21,"s","")
D22: =IF(C22,"kg","") | H22: =IF(G22,"m","") | L22: =IF(K22,"°C","") | V22: =IF(U22,"s","") | AH22: Promedio | AI22: =AVERAGE(AI11:AI20) -> 0.0051885389 | AJ22: s-1
D23: =IF(C23,"kg","") | H23: =IF(G23,"m","") | L23: =IF(K23,"°C","") | V23: =IF(U23,"s","") | AH23: Desv. Est. | AI23: =_xlfn.STDEV.S(AI11:AI20) -> 0.00030896434 | AJ23: s-1
D24: =IF(C24,"kg","") | H24: =IF(G24,"m","") | L24: =IF(K24,"°C","") | V24: =IF(U24,"s","")
D25: =IF(C25,"kg","") | H25: =IF(G25,"m","") | L25: =IF(K25,"°C","") | V25: =IF(U25,"s","")
D26: =IF(C26,"kg","") | H26: =IF(G26,"m","") | L26: =IF(K26,"°C","") | V26: =IF(U26,"s","")
D27: =IF(C27,"kg","") | H27: =IF(G27,"m","") | L27: =IF(K27,"°C","") | V27: =IF(U27,"s","")
D28: =IF(C28,"kg","") | H28: =IF(G28,"m","") | L28: =IF(K28,"°C","") | V28: =IF(U28,"s","")
D29: =IF(C29,"kg","") | H29: =IF(G29,"m","") | L29: =IF(K29,"°C","") | V29: =IF(U29,"s","")
D30: =IF(C30,"kg","") | H30: =IF(G30,"m","") | L30: =IF(K30,"°C","") | V30: =IF(U30,"s","")
D31: =IF(C31,"kg","") | H31: =IF(G31,"m","") | L31: =IF(K31,"°C","") | V31: =IF(U31,"s","")
D32: =IF(C32,"kg","") | H32: =IF(G32,"m","") | L32: =IF(K32,"°C","") | V32: =IF(U32,"s","")
D33: =IF(C33,"kg","") | H33: =IF(G33,"m","") | L33: =IF(K33,"°C","") | V33: =IF(U33,"s","")
D34: =IF(C34,"kg","") | H34: =IF(G34,"m","") | L34: =IF(K34,"°C","") | V34: =IF(U34,"s","")
D35: =IF(C35,"kg","") | H35: =IF(G35,"m","") | L35: =IF(K35,"°C","") | V35: =IF(U35,"s","")
... D56: =IF(C56,"kg","") | H56: =IF(G56,"m","") | L56: =IF(K56,"°C","") | V56: =IF(U56,"s","")
D57: =IF(C57,"kg","") | L57: =IF(K57,"°C","") | V57: =IF(U57,"s","")
D58: =IF(C58,"kg","") | L58: =IF(K58,"°C","") | V58: =IF(U58,"s","")
D59: =IF(C59,"kg","") | L59: =IF(K59,"°C","") | V59: =IF(U59,"s","")
D60: =IF(C60,"kg","") | L60: =IF(K60,"°C","") | V60: =IF(U60,"s","")
D61: =IF(C61,"kg","") | L61: =IF(K61,"°C","") | V61: =IF(U61,"s","")
D62: =IF(C62,"kg","") | L62: =IF(K62,"°C","") | V62: =IF(U62,"s","")
D63: =IF(C63,"kg","") | L63: =IF(K63,"°C","") | V63: =IF(U63,"s","")
...

Sheet Incertidumbres
B2: h promedio: | C2: =-Datos!$C$4*Datos!$O$4/(PI()*Datos!$G$4^2*Datos!$U$4)*LN((Datos!$AC$4-Datos!$K$4)/(Datos!$Y$4-Datos!$K$4)) -> 36.280697 | D2: W/(K m2)
G3: Variable
B4: m·c/(π·D²·τ): | C4: =Datos!$C$4*Datos!$O$4/(PI()*Datos!$G$4^2*Datos!$U$4) -> 25.923572 | D4: W/(K m2) | F4: Incertidumbre | G4: m | H4: c | I4: D | J4: τ | K4: T(τ) | L4: T0 | M4: T∞
F5: Resolución | G5: =Datos!C6/SQRT(12) -> 2.8867513e-09 | H5: - | I5: =Datos!G6/SQRT(12) -> 2.8867513e-06 | J5: =Datos!U6/SQRT(12) -> 0.0048112522 | K5: =Datos!AC6/SQRT(12) -> 0.028867513 | L5: =Datos!Y6/SQRT(12) -> 0.028867513 | M5: =Datos!K6/SQRT(12) -> 0.028867513
F6: Repetibilidad | G6: =Datos!C8/SQRT(COUNT(Datos!C11:C16)) -> 2.2211108e-08 | H6: - | I6: =Datos!G8/SQRT(COUNT(Datos!G11:G16)) -> 2.1081851e-06 | J6: =Datos!U7/SQRT(COUNT(Datos!U11:U20)) -> 0 | K6: =Datos!AC8/SQRT(COUNT(Datos!AC11:AC20)) -> 0.49181071 | L6: =Datos!Y8/SQRT(COUNT(Datos!Y11:Y20)) -> 1.664532 | M6: =Datos!K8/SQRT(COUNT(Datos!K11:K20)) -> 0.10219806
F7: Certificado | G7: =Datos!C7/2 -> 1e-06 | H7: - | I7: =Datos!G7/2 -> 1e-05 | J7: - | K7: =Datos!$AC$7/2 -> 0.3 | L7: =Datos!$Y$7/2 -> 0.3 | M7: =Datos!$K$7/2 -> 0.3
F9: Estándar | G9: =SQRT(SUMSQ(G5:G7)) -> 1.0002508e-06 | H9: =SQRT(SUMSQ(H5:H7)) -> 0 | I9: =SQRT(SUMSQ(I5:I7)) -> 1.0619688e-05 | J9: =SQRT(SUMSQ(J5:J7)) -> 0.0048112522 | K9: =SQRT(SUMSQ(K5:K7)) -> 0.57681116 | L9: =SQRT(SUMSQ(L5:L7)) -> 1.6915969 | M9: =SQRT(SUMSQ(M5:M7)) -> 0.3182417
F11: Coeficiente | G11: =C2/Datos!C4 -> 5272.5677 | H11: =C2/Datos!O4 -> 0.080623771 | I11: =-2/Datos!G4*Incertidumbres!C2 -> -6114.7242 | J11: =-C2/Datos!U4 -> -0.13437295 | K11: =-$C$4/(Datos!$AC$4-Datos!$K$4) -> -1.8663479 | L11: =$C$4/(Datos!$Y$4-Datos!$K$4) -> 0.46045421 | M11: =-$C$4*(1/(Datos!$AC$4-Datos!$K$4)-1/(Datos!$Y$4-Datos!$K$4)) -> -1.4058937
G12: =G13^2 -> 2.7813917e-05 | H12: =H13^2 -> 0 | I12: =I13^2 -> 0.0042167444 | J12: =J13^2 -> 4.1796505e-07 | K12: =K13^2 -> 1.1589174 | L12: =L13^2 -> 0.60668973 | M12: =M13^2 -> 0.20017927
F13: Aporte | G13: =G11*G9 -> 0.0052738901 | H13: =H11*H9 -> 0 | I13: =I11*I9 -> -0.064936464 | J13: =J11*J9 -> -0.00064650216 | K13: =K11*K9 -> -1.0765303 | L13: =L11*L9 -> 0.7789029 | M13: =M11*M9 -> -0.44741399
G14: =G12/$G$16 -> 1.4118514e-05 | H14: =H12/$G$16 -> 0 | I14: =I12/$G$16 -> 0.0021404453 | J14: =J12/$G$16 -> 2.1216161e-07 | K14: =K12/$G$16 -> 0.58827358 | L14: =L12/$G$16 -> 0.30795942 | M14: =M12/$G$16 -> 0.10161222
F15: Combinada | G15: =SQRT(SUMSQ(G13:M13)) -> 1.4035781 | H15: W/(K m2)
G16: =G15^2 -> 1.9700314
F17: Expanidida (k=2) | G17: =2*G15 -> 2.8071562 | H17: W/(K m2)
F19: Resultado final | G19: ="(" & ROUND(C2,1)& " ± " & ROUND(G17,1) & ")" -> (36.3 ± 2.8) | H19: W/(K m2)
